Workbook

Sheet Resumo 2026
A3: Processos em andamento | B3: Data: 06/04/2026
A4: Analista | B4: Senioridade/cargo | C4: Ag booking | D4: Ag embarque | E4: Embarcado | F4: Ag faturamento | G4: Total | H4: Meta
A5: Matheus Bourscheid | B5: Junior | C5: 7 | D5: 6 | E5: 38 | F5: 11 | G5: =SUM(C5:F5) -> 62 | H5: 70- 80 | I5: férias
A6: Tiago Schneider | B6: Senior | C6: 24 | D6: 25 | E6: 63 | F6: 20 | G6: =SUM(C6:F6) -> 132 | H6: 110-140
A7: Enila Kawely | B7: Senior | C7: 28 | D7: 14 | E7: 35 | F7: 27 | G7: =SUM(C7:F7) -> 104 | H7: 110-140 | I7: retorno de férias | M7: 640 | N7: 100
A8: Bruna Kelsch | B8: Senior | C8: 24 | D8: 14 | E8: 37 | F8: =56-37 -> 19 | G8: =SUM(C8:F8) -> 94 | H8: 110-140 | M8: 530 | N8: =M8*N7/M7 -> 82.8125
A9: Mariana Piccini | B9: Pleno | C9: 8 | D9: 8 | E9: 0 | F9: 1 | G9: =SUM(C9:F9) -> 17 | H9: 80-110 | I9: Inicio em 16/03
A10: Graziele Meytre | B10: Junior | C10: 0 | D10: 0 | E10: 0 | F10: 0 | G10: =SUM(C10:F10) -> 0 | H10: 70-80
A11: Kailane Claudino | B11: Assistente | C11: 0 | D11: 0 | E11: 0 | F11: 0 | G11: =SUM(C11:F11) -> 0 | H11: 010-20
A12: Manuela Silva | B12: Assistente | C12: 0 | D12: 0 | E12: 0 | F12: 0 | G12: =SUM(C12:F12) -> 0 | H12: 010-20
A13: Gabriel Hilgert | B13: Coordenador | C13: 0 | D13: 0 | E13: 0 | F13: 0 | G13: =SUM(C13:F13) -> 0 | H13: 0
A14: Matheus Ropelato | B14: Supervisor | C14: 18 | D14: 23 | E14: 38 | F14: 25 | G14: =SUM(C14:F14) -> 104 | H14: 0
G15: =SUM(G5:G14) -> 513
H16: minimo | I16: MÁXIMO
H17: =70+110+110+110+80+70+10+10 -> 570 | I17: =80+140+140+140+110+80+20+20 -> 730
A18: Chegadas confirmadas por mês: | B18: 1 | C18: 2 | D18: 3 | E18: 4 | F18: 5 | G18: 6 | H18: 7 | I18: 8 | J18: 9 | K18: 10 | L18: 11 | M18: 12 | N18: 12
A19: Analista | B19: Janeiro | C19: Fevereiro | D19: Março | E19: Abril | F19: Maio | G19: Junho | H19: Julho | I19: Agosto | J19: Setembro | K19: Outubro | L19: Novembro | M19: Dezembro | N19: Total
A20: Matheus Bourscheid | B20: =SUMIFS('Faturados 2026 HS'!$A:$A,'Faturados 2026 HS'!$AU:$AU,'Resumo 2026'!B$18,'Faturados 2026 HS'!$BA:$BA,'Resumo 2026'!$A20) -> 60 | C20: =SUMIFS('Faturados 2026 HS'!$A:$A,'Faturados 2026 HS'!$AU:$AU,'Resumo 2026'!C$18,'Faturados 2026 HS'!$BA:$BA,'Resumo 2026'!$A20) -> 66 | D20: =SUMIFS('Faturados 2026 HS'!$A:$A,'Faturados 2026 HS'!$AU:$AU,'Resumo 2026'!D$18,'Faturados 2026 HS'!$BA:$BA,'Resumo 2026'!$A20) -> 46 | N20: =SUM(B20:M20) -> 172
A21: Tiago Schneider | B21: =SUMIFS('Faturados 2026 HS'!$A:$A,'Faturados 2026 HS'!$AU:$AU,'Resumo 2026'!B$18,'Faturados 2026 HS'!$BA:$BA,'Resumo 2026'!$A21) -> 67 | C21: =SUMIFS('Faturados 2026 HS'!$A:$A,'Faturados 2026 HS'!$AU:$AU,'Resumo 2026'!C$18,'Faturados 2026 HS'!$BA:$BA,'Resumo 2026'!$A21) -> 47 | D21: =SUMIFS('Faturados 2026 HS'!$A:$A,'Faturados 2026 HS'!$AU:$AU,'Resumo 2026'!D$18,'Faturados 2026 HS'!$BA:$BA,'Resumo 2026'!$A21) -> 73 | N21: =SUM(B21:M21) -> 187
A22: Enila Kawely | B22: =SUMIFS('Faturados 2026 HS'!$A:$A,'Faturados 2026 HS'!$AU:$AU,'Resumo 2026'!B$18,'Faturados 2026 HS'!$BA:$BA,'Resumo 2026'!$A22) -> 45 | C22: =SUMIFS('Faturados 2026 HS'!$A:$A,'Faturados 2026 HS'!$AU:$AU,'Resumo 2026'!C$18,'Faturados 2026 HS'!$BA:$BA,'Resumo 2026'!$A22) -> 36 | D22: =SUMIFS('Faturados 2026 HS'!$A:$A,'Faturados 2026 HS'!$AU:$AU,'Resumo 2026'!D$18,'Faturados 2026 HS'!$BA:$BA,'Resumo 2026'!$A22) -> 29 | N22: =SUM(B22:M22) -> 110
A23: Bruna Kelsch | B23: =SUMIFS('Faturados 2026 HS'!$A:$A,'Faturados 2026 HS'!$AU:$AU,'Resumo 2026'!B$18,'Faturados 2026 HS'!$BA:$BA,'Resumo 2026'!$A23) -> 48 | C23: =SUMIFS('Faturados 2026 HS'!$A:$A,'Faturados 2026 HS'!$AU:$AU,'Resumo 2026'!C$18,'Faturados 2026 HS'!$BA:$BA,'Resumo 2026'!$A23) -> 57 | D23: =SUMIFS('Faturados 2026 HS'!$A:$A,'Faturados 2026 HS'!$AU:$AU,'Resumo 2026'!D$18,'Faturados 2026 HS'!$BA:$BA,'Resumo 2026'!$A23) -> 55 | N23: =SUM(B23:M23) -> 160
A24: Annie Audrien | B24: =SUMIFS('Faturados 2026 HS'!$A:$A,'Faturados 2026 HS'!$AU:$AU,'Resumo 2026'!B$18,'Faturados 2026 HS'!$BA:$BA,'Resumo 2026'!$A24) -> 29 | C24: =SUMIFS('Faturados 2026 HS'!$A:$A,'Faturados 2026 HS'!$AU:$AU,'Resumo 2026'!C$18,'Faturados 2026 HS'!$BA:$BA,'Resumo 2026'!$A24) -> 21 | D24: =SUMIFS('Faturados 2026 HS'!$A:$A,'Faturados 2026 HS'!$AU:$AU,'Resumo 2026'!D$18,'Faturados 2026 HS'!$BA:$BA,'Resumo 2026'!$A24) -> 4 | N24: =SUM(B24:M24) -> 54
A25: Graziele Meytre | B25: =SUMIFS('Faturados 2026 HS'!$A:$A,'Faturados 2026 HS'!$AU:$AU,'Resumo 2026'!B$18,'Faturados 2026 HS'!$BA:$BA,'Resumo 2026'!$A25) -> 0 | C25: =SUMIFS('Faturados 2026 HS'!$A:$A,'Faturados 2026 HS'!$AU:$AU,'Resumo 2026'!C$18,'Faturados 2026 HS'!$BA:$BA,'Resumo 2026'!$A25) -> 0 | D25: =SUMIFS('Faturados 2026 HS'!$A:$A,'Faturados 2026 HS'!$AU:$AU,'Resumo 2026'!D$18,'Faturados 2026 HS'!$BA:$BA,'Resumo 2026'!$A25) -> 0 | N25: =SUM(B25:M25) -> 0
A26: Kailane Claudino | B26: =SUMIFS('Faturados 2026 HS'!$A:$A,'Faturados 2026 HS'!$AU:$AU,'Resumo 2026'!B$18,'Faturados 2026 HS'!$BA:$BA,'Resumo 2026'!$A26) -> 0 | C26: =SUMIFS('Faturados 2026 HS'!$A:$A,'Faturados 2026 HS'!$AU:$AU,'Resumo 2026'!C$18,'Faturados 2026 HS'!$BA:$BA,'Resumo 2026'!$A26) -> 0 | D26: =SUMIFS('Faturados 2026 HS'!$A:$A,'Faturados 2026 HS'!$AU:$AU,'Resumo 2026'!D$18,'Faturados 2026 HS'!$BA:$BA,'Resumo 2026'!$A26) -> 0 | N26: =SUM(B26:M26) -> 0 | P26: =N29 -> 2
A27: Manuela Silva | B27: =SUMIFS('Faturados 2026 HS'!$A:$A,'Faturados 2026 HS'!$AU:$AU,'Resumo 2026'!B$18,'Faturados 2026 HS'!$BA:$BA,'Resumo 2026'!$A27) -> 0 | C27: =SUMIFS('Faturados 2026 HS'!$A:$A,'Faturados 2026 HS'!$AU:$AU,'Resumo 2026'!C$18,'Faturados 2026 HS'!$BA:$BA,'Resumo 2026'!$A27) -> 0 | D27: =SUMIFS('Faturados 2026 HS'!$A:$A,'Faturados 2026 HS'!$AU:$AU,'Resumo 2026'!D$18,'Faturados 2026 HS'!$BA:$BA,'Resumo 2026'!$A27) -> 0 | N27: =SUM(B27:M27) -> 0
A28: Mariana Piccini | B28: =SUMIFS('Faturados 2026 HS'!$A:$A,'Faturados 2026 HS'!$AU:$AU,'Resumo 2026'!B$18,'Faturados 2026 HS'!$BA:$BA,'Resumo 2026'!$A28) -> 0 | C28: =SUMIFS('Faturados 2026 HS'!$A:$A,'Faturados 2026 HS'!$AU:$AU,'Resumo 2026'!C$18,'Faturados 2026 HS'!$BA:$BA,'Resumo 2026'!$A28) -> 0 | D28: =SUMIFS('Faturados 2026 HS'!$A:$A,'Faturados 2026 HS'!$AU:$AU,'Resumo 2026'!D$18,'Faturados 2026 HS'!$BA:$BA,'Resumo 2026'!$A28) -> 0
A29: Gabriel Hilgert | B29: =SUMIFS('Faturados 2026 HS'!$A:$A,'Faturados 2026 HS'!$AU:$AU,'Resumo 2026'!B$18,'Faturados 2026 HS'!$BA:$BA,'Resumo 2026'!$A29) -> 0 | C29: =SUMIFS('Faturados 2026 HS'!$A:$A,'Faturados 2026 HS'!$AU:$AU,'Resumo 2026'!C$18,'Faturados 2026 HS'!$BA:$BA,'Resumo 2026'!$A29) -> 2 | D29: =SUMIFS('Faturados 2026 HS'!$A:$A,'Faturados 2026 HS'!$AU:$AU,'Resumo 2026'!D$18,'Faturados 2026 HS'!$BA:$BA,'Resumo 2026'!$A29) -> 0 | N29: =SUM(B29:M29) -> 2
A30: Matheus Ropelato | B30: =SUMIFS('Faturados 2026 HS'!$A:$A,'Faturados 2026 HS'!$AU:$AU,'Resumo 2026'!B$18,'Faturados 2026 HS'!$BA:$BA,'Resumo 2026'!$A30) -> 48 | C30: =SUMIFS('Faturados 2026 HS'!$A:$A,'Faturados 2026 HS'!$AU:$AU,'Resumo 2026'!C$18,'Faturados 2026 HS'!$BA:$BA,'Resumo 2026'!$A30) -> 57 | D30: =SUMIFS('Faturados 2026 HS'!$A:$A,'Faturados 2026 HS'!$AU:$AU,'Resumo 2026'!D$18,'Faturados 2026 HS'!$BA:$BA,'Resumo 2026'!$A30) -> 34 | N30: =SUM(B30:M30) -> 139
A31: Total Mês | B31: =SUM(B20:B30) -> 297 | C31: =SUM(C20:C30) -> 286 | D31: =SUM(D20:D30) -> 241 | E31: =SUM(E20:E30) -> 0 | F31: =SUM(F20:F30) -> 0 | G31: =SUM(G20:G30) -> 0 | H31: =SUM(H20:H30) -> 0 | I31: =SUM(I20:I30) -> 0 | ... N31: =SUM(N20:N30) -> 824
A33: Analista Senior: 110 - 140 (Bruna Kelsch, Enila Kawely, Tiago Schneider)
A34: Analista Pleno : 80-110 (não temos ninguém no momento)
A35: Analista Junior: 70-80 (Matheus Bourscheid, Graziele Meytre)
A36: Assistentes: 10 - 20 (Kailane Claudino e Manuela Silva)
F41: 94.16 | G41: 90.31 | H41: 98.09 | I41: 92.66 | J41: 100 | K41: 98.59

Sheet Faturados 2026 HS
D1: Nº processo house | E1: Cliente | F1: Notify | G1: Exportador | H1: ETD/ATD | I1: ETA/ATA | J1: Incoterm | K1: Nº conhecimento master | L1: Data processo | M1: Data abertura processo | N1: Situação embarque | O1: Companhia de transporte | P1: Conhecimentos | Q1: Origem | R1: Previsão início | S1: Navio | T1: Destino | U1: Navio transbordo | V1: Cliente - CNPJ | W1: Cliente Classificação | X1: Importador | Y1: Agente origem | Z1: Ref. cliente | AA1: Modalidade pgto. master | AB1: Ref. externa | AC1: Ref. interna | AD1: Tipo frete | AE1: Situação pagamento | AF1: Situação recebimento | AG1: Situação acerto agente | AH1: Situação CCT | AI1: Tipo do processo | AJ1: Metros cúbicos | AK1: Peso bruto | AL1: Peso cubado | AM1: Peso taxado | AN1: Tipo carga | AO1: Total container 20' | AP1: Total container 40' | AQ1: Equipamentos | AR1: Peso considerado | AS1: Data liberado faturamento | AT1: Data faturado | AU1: MÊS | AV1: Despachante | AW1: Data término | AX1: Números de embarque | AY1: Número oferta | AZ1: Containers | BA1: OPERACIONAL | BB1: FINANCEIRO OPERACIONAL | BC1: Número courrier | BD1: Lucro bruto momento processo | BE1: Lucro estimado corrente | BF1: Total pagamento processo | BG1: Total pago processo | BH1: Total recebimento processo | BI1: Total recebido processo | BJ1: Nível serviço | BK1: Data último acompanhamento | BL1: Tota pagamento corrente | BM1: Total pago corrente | BN1: Total recebimento corrente | BO1: Total recebido corrente | BP1: Previsão último desembarque | BQ1: Data último desembarque | BR1: Total TEUS | BS1: Tipo serviço aéreo | BT1: Situação tracking viagens | BU1: Seguro | BV1: Importância segurada | BW1: % seguro | BX1: Ativo | BY1: Ativo
A2: 1 | B2: Marítimo importação | C2: Back to back | D2: IM2307-25 | E2: VERALLIA BRASIL S.A. | F2: VERALLIA BRASIL S.A. | G2: CHINA BRIDGE HOLDINGS LIMITED | H2: 45998 | I2: 45665 | J2: FOB | K2: PSLSHASTS03736 | L2: 45978.66 | M2: 45978.66 | N2: Desembarcado | O2: KINGSHIP LINE LTDA | P2: SWS2511079 | Q2: SHANGHAI | S2: COSCO SHIPPING BRAZIL | T2: SANTOS | V2: 60.853.942/0013-88 | X2: VERALLIA BRASIL S.A. | Y2: (LCL) SHENZHEN SMOOTHWIN INTERNATIONAL | Z2: 5502170931 + 5502170928 | AA2: Collect | AB2: IM2307-25 | AE2: Parcialmente pago | AF2: Parcialmente recebido | AG2: Quitado | AH2: Não aplicável | AJ2: 1.585 | AK2: 3420 | AL2: 1585 | AN2: LCL | AO2: 0 | AP2: 0 | AR2: 3.42 | AS2: 46041 | AT2: 46041 | AU2: =MONTH(AT2) -> 1 | AY2: PF006185/25-01 | AZ2: SEGU9496518 | BA2: Tiago Schneider | BB2: Mariana Reis | BD2: 511.92 | BE2: 2839.95 | BF2: 30.66 | BG2: 28.94 | BH2: 542.58 | BI2: 275.04 | BK2: 46036.717 | BL2: 165.65 | BM2: 153.47 | BN2: 3005.6 | BO2: 1492.56 | BP2: 46030 | BQ2: 45665 | BR2: 0 | BT2: Sincronizado | BU2: Falso | BW2: 0 | BX2: Ativo | BY2: Ativo
A3: 1 | B3: Marítimo importação | C3: Back to back | D3: IM2308-25 | E3: VERALLIA BRASIL S.A. | F3: VERALLIA BRASIL S.A. | G3: CHINA BRIDGE HOLDINGS LIMITED | H3: 45998 | I3: 45665 | J3: FOB | K3: PSLSHASTS03735 | L3: 45978.664 | M3: 45978.664 | N3: Desembarcado | O3: KINGSHIP LINE LTDA | P3: SWS2511077 | Q3: SHANGHAI | S3: COSCO SHIPPING BRAZIL | T3: SANTOS | V3: 60.853.942/0007-30 | X3: VERALLIA BRASIL S.A. | Y3: (LCL) SHENZHEN SMOOTHWIN INTERNATIONAL | Z3: 5502173651 | AA3: Prepaid | AB3: IM2308-25 | AE3: Pago | AF3: Recebido | AG3: Quitado | AH3: Não aplicável | AJ3: 0.701 | AK3: 960 | AL3: 701 | AN3: LCL | AO3: 0 | AP3: 0 | AR3: 1 | AS3: 46045 | AT3: 46057 | AU3: =MONTH(AT3) -> 2 | AY3: PF006188/25-01 | AZ3: SEGU9496518 | BA3: Tiago Schneider | BB3: Mariana Reis | BD3: 169.35 | BE3: 955.27 | BF3: 590.35 | BG3: 590.35 | BH3: 759.7 | BI3: 759.7 | BK3: 46045.708 | BL3: 3259.2 | BM3: 3256.75 | BN3: 4214.47 | BO3: 4214.47 | BR3: 0 | BT3: Divergência viagens | BU3: Falso | BW3: 0 | BX3: Ativo | BY3: Ativo
A4: 1 | B4: Aéreo importação | C4: Back to back | D4: IA0455-25 | E4: SANDENNI INDUSTRIA & COMÉRCIO DE ARTIGOS OPTICOS LTDA | F4: SANDENNI INDUSTRIA & COMÉRCIO DE ARTIGOS OPTICOS LTDA | G4: WENZHOU GLASSES SHARE INDUSTRY DEVELOPMENT CO.,LTD | H4: 45911 | I4: 45917 | J4: EXW | K4: 016-77798140 | L4: 45905.401 | M4: 45905.401 | N4: Desembarcado | O4: UNITED AIRLINES | P4: BQDA2509005 | Q4: PEQUIM (BEIJING) | T4: GUARULHOS | V4: 19.090.436/0001-47 | X4: WINNING TRADING S.A. (SC) | Y4: BVL - BON VOYAGE LOGISTICS INC. | Z4: IMP.013/2025 - ILOG 3429/25 - ANTIGO IA0338-25 | AA4: Prepaid | AB4: 3429/25 | AE4: Pago | AF4: Recebido | AG4: Quitado | AH4: Desconsolidado | AJ4: 10.05 | AK4: 1700 | AL4: 1675 | AM4: 1700 | AN4: Aéreo | AR4: 1700 | AS4: 46043 | AT4: 46044 | AU4: =MONTH(AT4) -> 1 | AV4: LEADER LOGISTICS LTDA FILIAL ITJ | AY4: PF003135/25-10 | BA4: Annie Audrien | BD4: 343.01 | BE4: 2602.31 | BF4: 14196.48 | BG4: 14196.48 | BH4: 14539.49 | BI4: 14539.49 | BK4: 46043.735 | BL4: 78326.72 | BM4: 76945.08 | BN4: 80929.03 | BO4: 80929.03 | BP4: 45919.75 | BQ4: 45919.39 | BT4: Tracking inativo | BU4: Falso | BW4: 0 | BX4: Ativo | BY4: Ativo
A5: 1 | B5: Marítimo importação | C5: Back to back | D5: IM1496-25 | E5: OVERSEAS NETWORK SALES & MARKETING | F5: ENDURANCE COMERCIO ATACADISTA DE ARTIGOS PARA PRESENTES LTDA | G5: BAITAIXING SUPPLY CHAIN CO.,LIMITED | H5: 45896 | I5: 45931 | J5: CFR | K5: EGLV149505987694 | L5: 45889.604 | M5: 45889.604 | N5: Desembarcado | O5: EVERGREEN | P5: CSZ2508567 | Q5: YANTIAN | S5: EVER FAST | T5: NAVEGANTES | X5: ENDURANCE COMERCIO ATACADISTA DE ARTIGOS PARA PRESENTES LTDA | Y5: SHENZHEN SUPERSONIC CARGO, CO., LTD. | Z5: CSZ2508567 | AB5: IM1496-25 | AE5: Pago | AF5: Recebido | AG5: Sem acerto com agente | AH5: Não aplicável | AL5: 0 | AN5: FCL | AO5: 0 | AP5: 1 | AQ5: 40 HIGH CUBE | AR5: 0 | AS5: 46022 | AT5: 46029 | AU5: =MONTH(AT5) -> 1 | AY5: PF004090/25-01 | AZ5: TGBU5829514 | BA5: Bruna Kelsch | BD5: 634.93 | BE5: 3336.88 | BF5: 545.08 | BG5: 545.08 | BH5: 1180.01 | BI5: 1180.01 | BK5: 46022.383 | BL5: 3243.25 | BM5: 3243.25 | BN5: 6580.13 | BO5: 6580.13 | BP5: 45931 | BQ5: 45931 | BR5: 2 | BT5: Sincronizado | BU5: Falso | BW5: 0 | BX5: Ativo | BY5: Ativo
A6: 1 | B6: Demurrage | C6: Back to back | D6: DEMU0104-25 | E6: HD IMPORTADORA E DISTRIBUIDORA LTDA | F6: HD IMPORTADORA E DISTRIBUIDORA LTDA | G6: SHANDONG JINPENG GRINDING MATERIAL & TOOLS CO., LTD | H6: 45850.99 | I6: 45939 | J6: FOB | K6: ONEYTA5PV1521500 | L6: 45967.694 | M6: 45967.694 | N6: Desembarcado | O6: ONE | P6: KDSY25070012 | Q6: QINGDAO | S6: HMM OSLO | T6: PARANAGUA | U6: ONE PARANA | V6: 33.492.169/0001-65 | X6: HD IMPORTADORA E DISTRIBUIDORA LTDA | Y6: REACH LOGISTICS CO., LTD | Z6: 375667+381540 HD - IM1117-25 | AA6: Prepaid | AB6: DEMU0104-25 | AE6: Sem pagamento | AF6: Sem recebimento | AG6: Sem acerto com agente | AH6: Não aplicável | AL6: 0 | AN6: FCL | AO6: 0 | AP6: 3 | AQ6: 40 NOR | AR6: 0 | AT6: 46034 | AU6: =MONTH(AT6) -> 1 | AV6: Grupo Pinho | AY6: PF002997/25-03 | AZ6: BMOU9863811, OTPU6395803, TGHU9947522 | BA6: Matheus Bourscheid | BD6: 2444.4 | BE6: 13049.58 | BF6: 2325.6 | BG6: 2325.6 | BH6: 4770 | BI6: 4770 | BK6: 46010.585 | BL6: 13628.02 | BM6: 13628.02 | BN6: 26677.6 | BO6: 26677.6 | BP6: 45939 | BR6: 6 | BT6: Tracking inativo | BU6: Falso | BW6: 0 | BX6: Ativo | BY6: Ativo
A7: 1 | B7: Marítimo importação | C7: Back to back | D7: IM1770-25 | E7: OVERSEAS NETWORK SALES & MARKETING | F7: Ceres Atacadista Ltda | G7: ZHEJIANG PINZHONG IMP.& EXP.CO.,LIMITED | H7: 45902 | I7: 45939.892 | J7: CFR | K7: NGP2812555 | L7: 45918.602 | M7: 45918.602 | N7: Desembarcado | O7: COMPAGNIE GENERALE MARITIME - CMA CGM | P7: NGBNVT25090034 | Q7: NINGBO | S7: EVER FUTURE | T7: ITAJAI | X7: Ceres Atacadista Ltda | Y7: RPCARGO INTERNATIONAL FORWARDING (NINGBO) CO., LTD. | Z7: NGBNVT25090034 | AB7: IM1770-25 | AE7: Pago | AF7: Recebido | AG7: Sem acerto com agente | AH7: Não aplicável | AL7: 0 | AN7: FCL | AO7: 0 | AP7: 1 | AQ7: 40 HIGH CUBE | AR7: 0 | AS7: 46043 | AT7: 46044 | AU7: =MONTH(AT7) -> 1 | AY7: PF004843/25-01 | AZ7: TCKU6180214 | BA7: Bruna Kelsch | BD7: 601.45 | BE7: 3381.02 | BF7: 367.97 | BG7: 367.97 | BH7: 969.42 | BI7: 969.42 | BK7: 46043.769 | BL7: 2024.78 | BM7: 2024.78 | BN7: 5405.8 | BO7: 5405.8 | BP7: 45939.892 | BQ7: 45939.892 | BR7: 2 | BT7: Sincronizado | BU7: Falso | BW7: 0 | BX7: Ativo | BY7: Ativo
A8: 1 | B8: Aéreo importação | C8: Back to back | D8: IA0587-25 | E8: HENRICH & CIA LTDA | F8: HENRICH & CIA LTDA | G8: HONGKONG FUHENG LEATHER TRADE PTY LIMITED | H8: 45964 | I8: 45971 | J8: COURIER | K8: 9767764075 | L8: 45959.752 | M8: 45959.752 | N8: Desembarcado | O8: DHL | P8: 9767764075 | Q8: DONGGUAN | T8: PORTO ALEGRE | V8: 89.238.133/0001-04 | X8: HENRICH & CIA LTDA | Y8: LEADER LOGISTICS LTDA FILIAL ITJ | Z8: SAMPLE ORDER 0200/25 | AA8: Collect | AB8: IA0587-25 | AE8: Parcialmente pago | AF8: Recebido | AG8: Sem acerto com agente | AH8: Sem vínculo master | AJ8: 0.036 | AK8: 5 | AL8: 6 | AM8: 0.5 | AN8: Aéreo | AR8: 6 | AS8: 46045 | AT8: 46045 | AU8: =MONTH(AT8) -> 1 | AY8: PF005854/25-01 | BA8: Matheus Bourscheid | BD8: 56.69 | BE8: 418.96 | BF8: 667.93 | BG8: 665.02 | BH8: 724.62 | BI8: 724.62 | BK8: 46044.584 | BL8: 3677.69 | BM8: 3661.24 | BN8: 4096.65 | BO8: 4096.65 | BP8: 45973 | BQ8: 45971 | BT8: Tracking inativo | BU8: Falso | BW8: 0 | BX8: Ativo | BY8: Ativo
A9: 1 | B9: Aéreo importação | C9: Back to back | D9: IA0543-25 | E9: HENRICH & CIA LTDA | F9: HENRICH & CIA LTDA | G9: PRIME INTERNATIONAL INDIA PVT. LTD. | H9: 45962 | I9: 45971 | J9: COURIER | K9: 2512397005 | L9: 45944.724 | M9: 45944.724 | N9: Desembarcado | O9: DHL | P9: 2512397005 | Q9: DELHI | T9: PORTO ALEGRE | V9: 89.238.133/0001-04 | X9: HENRICH & CIA LTDA | Y9: LEADER LOGISTICS LTDA FILIAL ITJ | Z9: SAMPLE ORDER 0199/25 (PT1) - PRI/25-26/327 | AA9: Collect | AB9: IA0543-25 | AE9: Parcialmente pago | AF9: Recebido | AG9: Sem acerto com agente | AH9: Sem vínculo master | AJ9: 0.011 | AK9: 7 | AL9: 1.875 | AM9: 7 | AN9: Aéreo | AR9: 7 | AS9: 46045 | AT9: 46045 | AU9: =MONTH(AT9) -> 1 | AY9: PF005883/25-01 | BA9: Matheus Bourscheid | BD9: 113.69 | BE9: 713.68 | BF9: 268.93 | BG9: 263.4 | BH9: 382.62 | BI9: 382.62 | BK9: 46044.569 | BL9: 1449.48 | BM9: 1418.22 | BN9: 2163.16 | BO9: 2163.16 | BP9: 45971 | BQ9: 45971 | BT9: Tracking inativo | BU9: Falso | BW9: 0 | BX9: Ativo | BY9: Ativo
A10: 1 | B10: Aéreo importação | C10: Back to back | D10: IA0589-25 | E10: HENRICH & CIA LTDA | F10: HENRICH & CIA LTDA | G10: PRIME INTERNATIONAL INDIA PVT. LTD. | H10: 45962 | I10: 45971 | J10: COURIER | K10: 2512408485 | L10: 45961.676 | M10: 45961.676 | N10: Desembarcado | O10: DHL | P10: 2512408485 | Q10: DELHI | T10: PORTO ALEGRE | V10: 89.238.133/0001-04 | X10: HENRICH & CIA LTDA | Y10: LEADER LOGISTICS LTDA FILIAL ITJ | Z10: SAMPLE ORDER 0199/25 (PT2) - PRI/25-26/328 | AA10: Collect | AB10: IA0589-25 | AE10: Parcialmente pago | AF10: Recebido | AG10: Sem acerto com agente | AH10: Sem vínculo master | AJ10: 0.011 | AK10: 4.8 | AL10: 1.875 | AM10: 5 | AN10: Aéreo | AR10: 4.8 | AS10: 46045 | AT10: 46045 | AU10: =MONTH(AT10) -> 1 | AY10: PF005885/25-01 | BA10: Matheus Bourscheid | BD10: 88.22 | BE10: 576.39 | BF10: 685.56 | BG10: 671.74 | BH10: 773.78 | BI10: 773.78 | BK10: 46044.587 | BL10: 3798.17 | BM10: 3720.04 | BN10: 4374.56 | BO10: 4374.56 | BP10: 45972 | BQ10: 45971 | BT10: Tracking inativo | BU10: Falso | BW10: 0 | BX10: Ativo | BY10: Ativo
A11: 1 | B11: Aéreo importação | C11: Back to back | D11: IA0574-25 | E11: HENRICH & CIA LTDA | F11: HENRICH & CIA LTDA | G11: ITALTESSIL DI MARCONCINI S.R.L. - S.A.S. | H11: 45964 | I11: 45972 | J11: EXW | K11: 047-32471972 | L11: 45954.698 | M11: 45954.698 | N11: Desembarcado | O11: TAP | P11: 250900909472 | Q11: SEGRATE (MILAN) | T11: PORTO ALEGRE | V11: 89.238.133/0001-04 | X11: HENRICH & CIA LTDA | Y11: ALISPED S.P.A. | Z11: OC 1267872 | AA11: Prepaid | AB11: IA0574-25 | AE11: Pago | AF11: Recebido | AG11: Quitado | AH11: Desconsolidado | AJ11: 0.975 | AK11: 181.8 | AL11: 300 | AM11: 182 | AN11: Aéreo | AR11: 300 | AS11: 45985 | AT11: 46076 | AU11: =MONTH(AT11) -> 2 | AY11: PF005703/25-01 | BA11: Matheus Bourscheid | BB11: Mariana Reis | BD11: -312.13 | BE11: -1745 | BF11: 1115.93 | BG11: 1115.93 | BH11: 803.8 | BI11: 803.8 | BK11: 45982.723 | BL11: 6905.55 | BM11: 7061.28 | BN11: 5160.55 | BO11: 5160.55 | BP11: 45972 | BQ11: 45972 | BS11: Back to back | BT11: Tracking inativo | BU11: Falso | BV11: 10280 | BW11: 0 | BX11: Ativo | BY11: Ativo
A12: 1 | B12: Aéreo importação | C12: Back to back | D12: IA0599-25 | E12: HENRICH & CIA LTDA | F12: HENRICH & CIA LTDA | G12: PRIME INTERNATIONAL INDIA PVT. LTD. | H12: 45968 | I12: 45978 | J12: COURIER | K12: 2295719333 | L12: 45967.725 | M12: 45967.725 | N12: Desembarcado | O12: DHL | P12: 2295719333 | Q12: DELHI | T12: PORTO ALEGRE | V12: 89.238.133/0001-04 | X12: HENRICH & CIA LTDA | Y12: LEADER LOGISTICS LTDA FILIAL ITJ | Z12: SAMPLE ORDER 0199/25 (PT3) - PRI/25-26/331 | AA12: Collect | AB12: IA0599-25 | AE12: Parcialmente pago | AF12: Recebido | AG12: Sem acerto com agente | AH12: Sem vínculo master | AJ12: 0.011 | AK12: 9.4 | AL12: 1.875 | AM12: 9.4 | AN12: Aéreo | AR12: 9.4 | AS12: 46045 | AT12: 46045 | AU12: =MONTH(AT12) -> 1 | AY12: PF005883/25-01 | BA12: Matheus Bourscheid | BD12: 78.95 | BE12: 647.2 | BF12: 1121.84 | BG12: 1100.42 | BH12: 1200.79 | BI12: 1200.79 | BK12: 46044.591 | BL12: 6141.46 | BM12: 6020.36 | BN12: 6788.66 | BO12: 6788.66 | BP12: 45978 | BQ12: 45978 | BT12: Tracking inativo | BU12: Falso | BW12: 0 | BX12: Ativo | BY12: Ativo
A13: 1 | B13: Demurrage | C13: Back to back | D13: DEMU0118-25 | E13: B. & C. SPEAKERS BRASIL COMERCIO DE EQUIPAMENTOS DE AUDIO LTDA | F13: B. & C. SPEAKERS BRASIL COMERCIO DE EQUIPAMENTOS DE AUDIO LTDA | G13: B&C SPEAKERS S.P.A | H13: 45940 | I13: 45979 | J13: EXW | K13: MEDURL176654 | L13: 46010.621 | M13: 46010.621 | N13: Desembarcado | O13: MSC MEDITERRANEAN SHIPPING DO BRASIL LTDA. | P13: 944723/2025/09 | Q13: LIVORNO | S13: MSC MELINE | T13: NAVEGANTES | V13: 11.330.240/0001-70 | X13: B. & C. SPEAKERS BRASIL COMERCIO DE EQUIPAMENTOS DE AUDIO LTDA | Y13: ALISPED S.P.A. | Z13: SPED-25-01228 + ILOG 4684/25 + IM1866-25 | AB13: DEMU0118-25 | AE13: Sem pagamento | AF13: Sem recebimento | AG13: Sem acerto com agente | AH13: Não aplicável | AL13: 0 | AN13: FCL | AO13: 0 | AP13: 1 | AQ13: 40 HIGH CUBE | AR13: 0 | AT13: 46030 | AU13: =MONTH(AT13) -> 1 | AV13: LEADER LOGISTICS LTDA FILIAL ITJ | AY13: PF005074/25-01 | AZ13: MSMU7761965 | BA13: Matheus Bourscheid | BD13: 420.08 | BE13: 2853.43 | BF13: 0 | BG13: 0 | BH13: 420.08 | BI13: 420.08 | BK13: 46013.664 | BL13: 0 | BM13: 0 | BN13: 2853.43 | BO13: 2853.43 | BP13: 45979 | BR13: 2 | BT13: Tracking inativo | BU13: Falso | BW13: 0 | BX13: Ativo | BY13: Ativo
A14: 1 | B14: Aéreo importação | C14: Back to back | D14: IA0604-25 | E14: HENRICH & CIA LTDA | F14: HENRICH & CIA LTDA | G14: DONGGUAN GRAND ADVANCE TRADING CO.,LTD | H14: 45974 | I14: 45982 | J14: COURIER | K14: 8455006442 | L14: 45968.756 | M14: 45968.756 | N14: Desembarcado | O14: DHL | P14: 8455006442 | Q14: DONGGUAN | T14: PORTO ALEGRE | V14: 89.238.133/0001-04 | X14: HENRICH & CIA LTDA | Y14: LEADER LOGISTICS LTDA FILIAL ITJ | Z14: SAMPLE ORDER 0216/25 | AA14: Collect | AB14: IA0604-25 | AE14: Parcialmente pago | AF14: Recebido | AG14: Sem acerto com agente | AH14: Sem vínculo master | AJ14: 0.013 | AK14: 2.05 | AL14: 2.083 | AM14: 2.05 | AN14: Aéreo | AR14: 2.083 | AS14: 46051 | AT14: 46051 | AU14: =MONTH(AT14) -> 1 | AY14: PF006133/25-01 | BA14: Matheus Bourscheid | BD14: 57.19 | BE14: 383.65 | BF14: 309.21 | BG14: 302.96 | BH14: 366.4 | BI14: 366.4 | BK14: 46051.708 | BL14: 1687.81 | BM14: 1652.48 | BN14: 2071.46 | BO14: 2071.46 | BP14: 45982 | BQ14: 45982 | BT14: Tracking inativo | BU14: Falso | BW14: 0 | BX14: Ativo | BY14: Ativo
A15: 1 | B15: Aéreo importação | C15: Back to back | D15: IA0608-25 | E15: HENRICH & CIA LTDA | F15: HENRICH & CIA LTDA | G15: DONGYI LEATHER (HK) LIMITED | H15: 45973 | I15: 45982 | J15: COURIER | K15: 6489424255 | L15: 45971.723 | M15: 45971.723 | N15: Desembarcado | O15: DHL | P15: 6489424255 | Q15: DONGGUAN | T15: PORTO ALEGRE | V15: 89.238.133/0001-04 | X15: HENRICH & CIA LTDA | Y15: LEADER LOGISTICS LTDA FILIAL ITJ | Z15: SAMPLE ORDER 0212/25 | AA15: Collect | AB15: IA0608-25 | AE15: Parcialmente pago | AF15: Recebido | AG15: Sem acerto com agente | AH15: Sem vínculo master | AJ15: 0.039 | AK15: 5.8 | AL15: 6.5 | AM15: 6.5 | AN15: Aéreo | AR15: 6.5 | AS15: 46051 | AT15: 46051 | AU15: =MONTH(AT15) -> 1 | AY15: PF006095/25-01 | BA15: Matheus Bourscheid | BD15: 47.14 | BE15: 416.72 | BF15: 758.67 | BG15: 743.33 | BH15: 805.81 | BI15: 805.81 | BK15: 46051.706 | BL15: 4138.96 | BM15: 4052.24 | BN15: 4555.68 | BO15: 4555.68 | BP15: 45982 | BQ15: 45982 | BT15: Tracking inativo | BU15: Falso | BW15: 0 | BX15: Ativo | BY15: Ativo
A16: 1 | B16: Demurrage | C16: Back to back | D16: DEMU0121-25 | E16: METALURGICA DE TONI LTDA | F16: METALURGICA DE TONI LTDA | G16: HISENER INDUSTRIAL CO.,LTD | H16: 45936.372 | I16: 45984 | J16: FOB | K16: ONEYSHAFT8272300 | L16: 46010.651 | M16: 46010.651 | N16: Desembarcado | O16: ONE | P16: KDSY25090147 | Q16: SHANGHAI | S16: ONE STRENGTH | T16: RIO GRANDE | U16: HYUNDAI INTEGRAL | V16: 89.041.560/0001-06 | X16: METALURGICA DE TONI LTDA | Y16: REACH LOGISTICS CO., LTD | Z16: 026-25 - Hisener - IM1787-25 | AA16: Collect | AB16: DEMU0121-25 | AE16: Sem pagamento | AF16: Sem recebimento | AG16: Sem acerto com agente | AH16: Não aplicável | AJ16: 21.53 | AK16: 24680.59 | AL16: 21530 | AN16: FCL | AO16: 0 | AP16: 1 | AQ16: 40 NOR | AR16: 24.681 | AT16: 46034 | AU16: =MONTH(AT16) -> 1 | AY16: PF004848/25-02 | AZ16: TTNU8772441 | BA16: Matheus Bourscheid | BD16: 1179.5 | BE16: 6603.02 | BF16: 0 | BG16: 0 | BH16: 1179.5 | BI16: 1179.5 | BK16: 46021.684 | BL16: 0 | BM16: 0 | BN16: 6603.02 | BO16: 6603.02 | BP16: 45984 | BQ16: 45984 | BR16: 2 | BT16: Tracking inativo | BU16: Verdadeiro | BW16: 0 | BX16: Ativo | BY16: Ativo
A17: 1 | B17: Aéreo importação | C17: Back to back | D17: IA0607-25 | E17: HENRICH & CIA LTDA | F17: HENRICH & CIA LTDA | G17: CONCERIA M2 S.R.L. | H17: 45982 | I17: 45987 | J17: COURIER | K17: 5007582440 | L17: 45971.719 | M17: 45971.719 | N17: Desembarcado | O17: DHL | P17: 5007582440 | Q17: MALPENSA (MILAN) | T17: PORTO ALEGRE | V17: 89.238.133/0001-04 | X17: HENRICH & CIA LTDA | Y17: LEADER LOGISTICS LTDA FILIAL ITJ | Z17: SAMPLE ORDER 0219/25 | AA17: Collect | AB17: IA0607-25 | AE17: Pago | AF17: Recebido | AG17: Sem acerto com agente | AH17: Sem vínculo master | AJ17: 0.012 | AK17: 2 | AL17: 2 | AM17: 2 | AN17: Aéreo | AR17: 2 | AS17: 46078 | AT17: 46078 | AU17: =MONTH(AT17) -> 2 | AY17: PF006244/25-01 | BA17: Matheus Bourscheid | BD17: 70.19 | BE17: 332.06 | BF17: 351.67 | BG17: 351.67 | BH17: 421.86 | BI17: 421.86 | BK17: 46078.451 | BL17: 1939.34 | BM17: 1939.34 | BN17: 2271.4 | BO17: 2271.4 | BP17: 45989 | BQ17: 45987 | BT17: Tracking inativo | BU17: Falso | BW17: 0 | BX17: Ativo | BY17: Ativo
A18: 1 | B18: Demurrage | C18: Back to back | D18: DEMU0006-26 | E18: BRX IMPORT E EXPORT LTDA | F18: Self It Academias Holding S.A. | G18: SHUHUASPORTS CO., LTD | H18: 45911 | I18: 45988 | J18: FOB | K18: MEDUYQ162735 | L18: 46024.662 | M18: 46024.662 | N18: Desembarcado | O18: MSC MEDITERRANEAN SHIPPING DO BRASIL LTDA. | P18: ZJQRSE250640R | Q18: XIAMEN | S18: ZIM MOUNT DENALI | T18: Suape | U18: MSC AURIGA | V18: 16.690.730/0001-00 | X18: BRX IMPORT E EXPORT LTDA | Y18: NINGBO QR INTERNATIONAL LOGISTIC CO.,LTD | Z18: BRX-228 - IM1564-25 | AA18: Collect | AB18: DEMU0006-26 | AE18: Sem pagamento | AF18: Sem recebimento | AG18: Sem acerto com agente | AH18: Não aplicável | AL18: 0 | AN18: FCL | AO18: 0 | AP18: 3 | AQ18: 40 HIGH CUBE | AR18: 0 | AT18: 46052 | AU18: =MONTH(AT18) -> 1 | AV18: MasterSul | AY18: PF004206/25-02 | AZ18: CAIU4821351, FFAU2387078, MSDU7221641 | BA18: Matheus Bourscheid | BD18: 2250 | BE18: 12386.18 | BF18: 0 | BG18: 0 | BH18: 2250 | BI18: 2250 | BK18: 46031.73 | BL18: 0 | BM18: 0 | BN18: 12386.18 | BO18: 12386.18 | BP18: 45990 | BR18: 6 | BT18: Tracking inativo | BU18: Falso | BW18: 0 | BX18: Ativo | BY18: Ativo
A19: 1 | B19: Demurrage | C19: Back to back | D19: DEMU0004-26 | E19: BRX IMPORT E EXPORT LTDA | F19: Self It Academias Holding S.A. | G19: SHUHUASPORTS CO., LTD | H19: 45911 | I19: 45988 | J19: FOB | K19: MEDUYQ162727 | L19: 46024.635 | M19: 46024.635 | N19: Desembarcado | O19: MSC MEDITERRANEAN SHIPPING DO BRASIL LTDA. | P19: ZJQRSE250642R | Q19: XIAMEN | S19: ZIM MOUNT DENALI | T19: Suape | U19: MSC AURIGA | V19: 16.690.730/0001-00 | X19: BRX IMPORT E EXPORT LTDA | Y19: NINGBO QR INTERNATIONAL LOGISTIC CO.,LTD | Z19: BRX-230 - IM1563-25 | AA19: Collect | AB19: DEMU0004-26 | AE19: Sem pagamento | AF19: Sem recebimento | AG19: Sem acerto com agente | AH19: Não aplicável | AL19: 0 | AN19: FCL | AO19: 0 | AP19: 3 | AQ19: 40 HIGH CUBE | AR19: 0 | AT19: 46052 | AU19: =MONTH(AT19) -> 1 | AV19: MasterSul | AY19: PF004206/25-02 | AZ19: CAAU7894220, MSDU8248694, MSNU7384572 | BA19: Matheus Bourscheid | BD19: 250 | BE19: 1376.24 | BF19: 0 | BG19: 0 | BH19: 250 | BI19: 250 | BK19: 46031.722 | BL19: 0 | BM19: 0 | BN19: 1376.24 | BO19: 1376.24 | BP19: 45988 | BR19: 6 | BT19: Tracking inativo | BU19: Falso | BW19: 0 | BX19: Ativo | BY19: Ativo
A20: 1 | B20: Demurrage | C20: Back to back | D20: DEMU0005-26 | E20: BRX IMPORT E EXPORT LTDA | F20: Self It Academias Holding S.A. | G20: SHUHUASPORTS CO., LTD | H20: 45911 | I20: 45988 | J20: FOB | K20: MEDUYQ162842 | L20: 46024.65 | M20: 46024.65 | N20: Desembarcado | O20: MSC MEDITERRANEAN SHIPPING DO BRASIL LTDA. | P20: ZJQRSE250641R | Q20: XIAMEN | S20: ZIM MOUNT DENALI | T20: Suape | U20: MSC AURIGA | V20: 16.690.730/0001-00 | X20: BRX IMPORT E EXPORT LTDA | Y20: NINGBO QR INTERNATIONAL LOGISTIC CO.,LTD | Z20: BRX-229 - IM1562-25 | AA20: Collect | AB20: DEMU0005-26 | AE20: Sem pagamento | AF20: Sem recebimento | AG20: Sem acerto com agente | AH20: Não aplicável | AL20: 0 | AN20: FCL | AO20: 0 | AP20: 3 | AQ20: 40 HIGH CUBE | AR20: 0 | AT20: 46052 | AU20: =MONTH(AT20) -> 1 | AV20: MasterSul | AY20: PF004206/25-02 | AZ20: CAAU5105195, MSDU8131590, TCNU3713490 | BA20: Matheus Bourscheid | BD20: 2500 | BE20: 13762.42 | BF20: 0 | BG20: 0 | BH20: 2500 | BI20: 2500 | BK20: 46031.725 | BL20: 0 | BM20: 0 | BN20: 13762.42 | BO20: 13762.42 | BP20: 45988 | BR20: 6 | BT20: Tracking inativo | BU20: Falso | BW20: 0 | BX20: Ativo | BY20: Ativo
A21: 1 | B21: Demurrage | C21: Back to back | D21: DEMU0027-26 | E21: INDUSTRIA DE CALCADOS BEIRA RIO LTDA | F21: INDUSTRIA DE CALCADOS BEIRA RIO LTDA | G21: XIAMEN LONGSHUNDA TRADING CO., LTD | H21: 45957 | I21: 45991 | J21: FOB | K21: MAEU260440519 | L21: 46041.605 | M21: 46041.605 | N21: Desembarcado | O21: MAERSK | P21: KDSY25100010 | Q21: XIAMEN | S21: PANCON CHAMPION | T21: SANTOS | U21: CAP SAN ARTEMISSIO | V21: 43.176.072/0001-05 | X21: INDUSTRIA DE CALCADOS BEIRA RIO LTDA | Y21: REACH LOGISTICS CO., LTD | Z21: KJ20250408 // ILOG: 4458/25 - IM1928-25 | AA21: Collect | AB21: DEMU0027-26 | AE21: Sem pagamento | AF21: Sem recebimento | AG21: Sem acerto com agente | AH21: Não aplicável | AJ21: 50 | AK21: 26380 | AL21: 50000 | AN21: FCL | AO21: 0 | AP21: 1 | AQ21: 40 HIGH CUBE | AR21: 50 | AT21: 46051 | AU21: =MONTH(AT21) -> 1 | AY21: PF005010/25-02 | AZ21: MSKU0814912 | BA21: Matheus Bourscheid | BD21: 1972.64 | BE21: 11313.53 | BF21: 4102.36 | BG21: 4102.36 | BH21: 6075 | BI21: 6075 | BK21: 46043.711 | BL21: 22728.58 | BM21: 22728.58 | BN21: 34042.11 | BO21: 34042.11 | BP21: 45991.292 | BR21: 2 | BT21: Tracking inativo | BU21: Falso | BW21: 0 | BX21: Ativo | BY21: Ativo
A22: 1 | B22: Aéreo importação | C22: Back to back | D22: IA0624-25 | E22: HENRICH & CIA LTDA | F22: HENRICH & CIA LTDA | G22: HUNG HING METAL MANUFACTORY LTD | H22: 45987 | I22: 45992 | J22: COURIER | K22: 3206989015 | L22: 45974.722 | M22: 45974.722 | N22: Desembarcado | O22: DHL | Q22: DONGGUAN | T22: PORTO ALEGRE | V22: 89.238.133/0001-04 | X22: HENRICH & CIA LTDA | Z22: SAMPLE ORDER 0220/25 | AA22: Collect | AB22: IA0624-25 | AE22: Pago | AF22: Recebido | AG22: Sem acerto com agente | AH22: Sem AWB house | AJ22: 0.016 | AK22: 1 | AL22: 2.621 | AM22: 2.5 | AN22: Aéreo | AR22: 2.621 | AS22: 46045 | AT22: 46045 | AU22: =MONTH(AT22) -> 1 | AY22: PF004032/25-01 | BA22: Matheus Bourscheid | BD22: 64.83 | BE22: 414.87 | BF22: 244.98 | BG22: 244.98 | BH22: 309.81 | BI22: 309.81 | BK22: 46044.59 | BL22: 1336.66 | BM22: 1336.66 | BN22: 1751.53 | BO22: 1751.53 | BP22: 45995 | BQ22: 45992 | BT22: Tracking inativo | BU22: Falso | BW22: 0 | BX22: Ativo | BY22: Ativo
A23: 1 | B23: Marítimo importação | C23: Back to back | D23: IM2078-25 | E23: OVERSEAS NETWORK SALES & MARKETING | F23: ENGEL'S GLOBAL COMERCIO EXTERIOR LTDA | G23: YIWU HONGSHENG IMP AND EXP CO., LIMITED | H23: 45958.035 | I23: 45994 | J23: CFR | K23: YMJAB232105572 | L23: 45951.613 | M23: 45951.613 | N23: Desembarcado | O23: YANG MING | P23: UNI25100097 | Q23: NINGBO | S23: COSCO SHIPPING PERU | T23: NAVEGANTES | X23: ENGEL'S GLOBAL COMERCIO EXTERIOR LTDA | Y23: NINGBO UNION NB INTERNATIONAL FREIGHT AGENCY CO.,LTD. | Z23: UNI25100097 | AB23: IM2078-25 | AE23: Pago | AF23: Recebido | AG23: Quitado | AH23: Não aplicável | AL23: 0 | AN23: FCL | AO23: 0 | AP23: 1 | AQ23: 40 HIGH CUBE | AR23: 0 | AS23: 46024 | AT23: 46029 | AU23: =MONTH(AT23) -> 1 | AY23: PF005601/25-01 | AZ23: YMMU6797732 | BA23: Bruna Kelsch | BD23: 534.15 | BE23: 3047.1 | BF23: 364.37 | BG23: 364.37 | BH23: 898.52 | BI23: 898.52 | BK23: 46024.617 | BL23: 2150.39 | BM23: 2150.39 | BN23: 5197.49 | BO23: 5178.46 | BP23: 45994 | BQ23: 45994 | BR23: 2 | BT23: Sincronizado | BU23: Falso | BW23: 0 | BX23: Ativo | BY23: Ativo
A24: 1 | B24: Marítimo importação | C24: Back to back | D24: IM2018-25 | E24: OVERSEAS NETWORK SALES & MARKETING | F24: ENGEL'S GLOBAL COMERCIO EXTERIOR LTDA | G24: YIWU HONGSHENG IMP AND EXP CO., LIMITED | H24: 45960 | I24: 45994 | J24: CFR | K24: EGLV143550143379 | L24: 45945.559 | M24: 45945.559 | N24: Desembarcado | O24: EVERGREEN | P24: UNI25100054 | Q24: NINGBO | S24: KOTA PUSAKA | T24: ITAJAI | X24: ENGEL'S GLOBAL COMERCIO EXTERIOR LTDA | Y24: NINGBO UNION NB INTERNATIONAL FREIGHT AGENCY CO.,LTD. | Z24: UNI25100054 | AB24: IM2018-25 | AE24: Pago | AF24: Recebido | AG24: Quitado | AH24: Não aplicável | AL24: 0 | AN24: FCL | AO24: 0 | AP24: 1 | AQ24: 40 HIGH CUBE | AR24: 0 | AS24: 46022 | AT24: 46029 | AU24: =MONTH(AT24) -> 1 | AY24: PF005448/25-01 | AZ24: TXGU6131372 | BA24: Bruna Kelsch | BD24: 547.33 | BE24: 3107.22 | BF24: 466.19 | BG24: 466.19 | BH24: 1013.52 | BI24: 1013.52 | BK24: 46022.393 | BL24: 2750.02 | BM24: 2750.02 | BN24: 5857.24 | BO24: 5843.71 | BP24: 45999 | BQ24: 45994 | BR24: 2 | BT24: Sincronizado | BU24: Falso | BW24: 0 | BX24: Ativo | BY24: Ativo
A25: 1 | B25: Marítimo importação | C25: Back to back | D25: IM2051-25 | E25: OVERSEAS NETWORK SALES & MARKETING | F25: ENGEL'S GLOBAL COMERCIO EXTERIOR LTDA | G25: YIWU HONGSHENG IMP AND EXP CO., LIMITED | H25: 45963 | I25: 45994 | J25: CFR | K25: EGLV149507446551 | L25: 45950.523 | M25: 45950.523 | N25: Desembarcado | O25: EVERGREEN | P25: CSZ2510566 | Q25: YANTIAN | S25: KOTA PUSAKA | T25: ITAJAI | X25: ENGEL'S GLOBAL COMERCIO EXTERIOR LTDA | Y25: SHENZHEN SUPERSONIC CARGO, CO., LTD. | Z25: CSZ2510566 | AB25: IM2051-25 | AE25: Pago | AF25: Recebido | AG25: Sem acerto com agente | AH25: Não aplicável | AL25: 0 | AN25: FCL | AO25: 0 | AP25: 1 | AQ25: 40 HIGH CUBE | AR25: 0 | AS25: 46022 | AT25: 46029 | AU25: =MONTH(AT25) -> 1 | AY25: PF005561/25-01 | AZ25: EGHU9442583 | BA25: Bruna Kelsch | BD25: 456.29 | BE25: 2571.41 | BF25: 412.23 | BG25: 412.23 | BH25: 868.52 | BI25: 868.52 | BK25: 46030.423 | BL25: 2452.75 | BM25: 2452.75 | BN25: 5024.16 | BO25: 5024.16 | BP25: 45999 | BQ25: 45994 | BR25: 2 | BT25: Sincronizado | BU25: Falso | BW25: 0 | BX25: Ativo | BY25: Ativo
A26: 1 | B26: Marítimo importação | C26: Back to back | D26: IM1993-25 | E26: OVERSEAS NETWORK SALES & MARKETING | F26: ENGEL MACHINERY (SHANGHAI) CO., LTD. | G26: YIWU HONGSHENG IMP AND EXP CO., LIMITED | H26: 45960.801 | I26: 45994 | J26: CFR | K26: OOLU2163052210 | L26: 45943.635 | M26: 45943.635 | N26: Desembarcado | O26: OOCL | P26: TCNB2510328 | Q26: NINGBO | S26: KOTA PUSAKA | T26: ITAJAI | X26: ENGEL'S GLOBAL COMERCIO EXTERIOR LTDA | Y26: XIAMEN TRANS-CHINA LOGISTICS CO. | Z26: TCNB2510328 | AA26: Prepaid | AB26: IM1993-25 | AE26: Pago | AF26: Recebido | AG26: Em aberto | AH26: Não aplicável | AL26: 0 | AN26: FCL | AO26: 0 | AP26: 1 | AQ26: 40 HIGH CUBE | AR26: 0 | AS26: 46022 | AT26: 46029 | AU26: =MONTH(AT26) -> 1 | AY26: PF005389/25-01 | AZ26: OOCU9457365 | BA26: Bruna Kelsch | BD26: 715.6 | BE26: 4158.87 | BF26: 261.69 | BG26: 261.69 | BH26: 977.29 | BI26: 927.29 | BK26: 46042.562 | BL26: 1485 | BM26: 1485 | BN26: 5643.87 | BO26: 5364.16 | BP26: 45996 | BQ26: 45994 | BR26: 2 | BT26: Sincronizado | BU26: Falso | BW26: 0 | BX26: Ativo | BY26: Ativo
A27: 1 | B27: Marítimo importação | C27: Back to back | D27: IM2047-25 | E27: OVERSEAS NETWORK SALES & MARKETING | F27: ENGEL'S GLOBAL COMERCIO EXTERIOR LTDA | G27: YIWU HONGSHENG IMP AND EXP CO., LIMITED | H27: 45963 | I27: 45994 | J27: CFR | K27: EGLV149507446542 | L27: 45950.318 | M27: 45950.318 | N27: Desembarcado | O27: EVERGREEN | P27: CSZ2510562 | Q27: YANTIAN | S27: KOTA PUSAKA | T27: ITAJAI | X27: ENGEL'S GLOBAL COMERCIO EXTERIOR LTDA | Y27: SHENZHEN SUPERSONIC CARGO, CO., LTD. | Z27: CSZ2510562 | AB27: IM2047-25 | AE27: Pago | AF27: Recebido | AG27: Sem acerto com agente | AH27: Não aplicável | AL27: 0 | AN27: FCL | AO27: 0 | AP27: 1 | AQ27: 40 HIGH CUBE | AR27: 0 | AT27: 46108 | AU27: =MONTH(AT27) -> 3 | AY27: PF005545/25-01 | AZ27: EISU9343037 | BA27: Bruna Kelsch | BD27: 615.8 | BE27: 3340.02 | BF27: 456.23 | BG27: 456.23 | BH27: 1072.03 | BI27: 1072.03 | BK27: 46035.654 | BL27: 2715.55 | BM27: 2715.55 | BN27: 6055.57 | BO27: 6055.57 | BP27: 45999 | BQ27: 45994 | BR27: 2 | BT27: Sincronizado | BU27: Falso | BW27: 0 | BX27: Ativo | BY27: Ativo
A28: 1 | B28: Marítimo importação | C28: Back to back | D28: IM2252-25 | E28: OVERSEAS NETWORK SALES & MARKETING | F28: ENGEL'S GLOBAL COMERCIO EXTERIOR LTDA | G28: YIWU HONGSHENG IMP AND EXP CO., LIMITED | H28: 45960 | I28: 45994 | J28: CFR | K28: NGP2953297 | L28: 45971.635 | M28: 45971.635 | N28: Desembarcado | O28: COMPAGNIE GENERALE MARITIME - CMA CGM | P28: NGBNVT25100190 | Q28: NINGBO | S28: KOTA PUSAKA | T28: ITAJAI | X28: ENGEL'S GLOBAL COMERCIO EXTERIOR LTDA | Y28: RPCARGO INTERNATIONAL FORWARDING (NINGBO) CO., LTD. | Z28: NGBNVT25100190 | AB28: IM2252-25 | AE28: Pago | AF28: Recebido | AG28: Sem acerto com agente | AH28: Não aplicável | AJ28: 68 | AK28: 19821.6 | AL28: 68000 | AN28: FCL | AO28: 0 | AP28: 1 | AQ28: 40 HIGH CUBE | AR28: 68 | AT28: 46108 | AU28: =MONTH(AT28) -> 3 | AY28: PF006019/25-01 | AZ28: GESU6274261 | BA28: Bruna Kelsch | BD28: 620.86 | BE28: 3496.78 | BF28: 312.42 | BG28: 312.42 | BH28: 933.28 | BI28: 933.28 | BK28: 46038.726 | BL28: 1775 | BM28: 1775 | BN28: 5271.78 | BO28: 5271.78 | BP28: 45999 | BQ28: 45994 | BR28: 2 | BT28: Tracking inativo | BU28: Falso | BW28: 0 | BX28: Ativo | BY28: Ativo
A29: 1 | B29: Aéreo importação | C29: Back to back | D29: IA0643-25 | E29: CALCADOS RAMARIM LTDA | F29: CALCADOS RAMARIM LTDA | G29: TSAN CHEN TEXTILE TRADING CO., LTD | H29: 45988 | I29: 45995 | J29: EXW | L29: 45985.626 | M29: 45985.626 | N29: Desembarcado | O29: DHL | Q29: TAOYUAN INTL (TAIPEI) | T29: Novo Hamburgo - Cidade | V29: 88.104.328/0001-07 | X29: CALCADOS RAMARIM LTDA | Y29: LEADER LOGISTICS LTDA FILIAL ITJ | Z29: OC 807051 - PI-20251119 | AA29: Collect | AB29: IA0643-25 | AE29: Pago | AF29: Recebido | AG29: Sem acerto com agente | AH29: Sem AWB house | AJ29: 0.015 | AK29: 7.4 | AL29: 2.562 | AM29: 7.5 | AN29: Aéreo | AR29: 7.4 | AS29: 46064 | AT29: 46064 | AU29: =MONTH(AT29) -> 2 | AY29: PF006281/25-01 | BA29: Bruna Kelsch | BD29: 165.32 | BE29: 894.49 | BF29: 696.66 | BG29: 696.66 | BH29: 861.98 | BI29: 861.98 | BK29: 46002.397 | BL29: 3806.8 | BM29: 3806.8 | BN29: 4701.29 | BO29: 4701.29 | BP29: 45996 | BQ29: 45995 | BT29: Tracking inativo | BU29: Falso | BW29: 0 | BX29: Ativo | BY29: Ativo
A30: 1 | B30: Marítimo importação | C30: Back to back | D30: IM1970-25 | E30: BBB COMERCIO ELETRONICO LTDA | F30: BBB COMERCIO ELETRONICO LTDA | G30: SONIFEST S.A | H30: 45960.811 | I30: 45996 | J30: FOB | K30: CMDUNGP2920609 | L30: 45940.427 | M30: 45940.427 | N30: Desembarcado | O30: COMPAGNIE GENERALE MARITIME - CMA CGM | P30: KDSY25100063 | Q30: NINGBO | S30: KOTA PUSAKA | T30: ITAJAI | V30: 34.098.618/0002-39 | X30: BBB COMERCIO ELETRONICO LTDA | Y30: REACH LOGISTICS CO., LTD | Z30: ILOG 4909/25 - L-SON250827 | AA30: Prepaid | AB30: 4909/25 | AE30: Pago | AF30: Recebido | AG30: Quitado | AH30: Não aplicável | AJ30: 50 | AK30: 24420 | AL30: 50000 | AN30: FCL | AO30: 0 | AP30: 1 | AQ30: 40 HIGH CUBE | AR30: 50 | AS30: 46022 | AT30: 46028 | AU30: =MONTH(AT30) -> 1 | AV30: LEADER LOGISTICS LTDA FILIAL ITJ | AY30: PF005318/25-01 | AZ30: CMAU8830267 | BA30: Matheus Bourscheid | BD30: 202.09 | BE30: 1595.63 | BF30: 2448.48 | BG30: 2448.48 | BH30: 2650.57 | BI30: 2650.57 | BK30: 46022.459 | BL30: 13267.5 | BM30: 12910.47 | BN30: 14863.13 | BO30: 14863.13 | BP30: 45996.25 | BQ30: 45996 | BR30: 2 | BT30: Sincronizado | BU30: Falso | BW30: 0 | BX30: Ativo | BY30: Ativo
A31: 1 | B31: Marítimo importação | C31: Back to back | D31: IM1471-25 | E31: CALCADOS RAMARIM LTDA | F31: CALCADOS RAMARIM LTDA | G31: TIEN KANG CO., LTD | H31: 45915 | I31: 45996.264 | J31: EXW | L31: 45887.462 | M31: 45887.462 | N31: Desembarcado | O31: MSL | P31: LHKTCG-25090344RIG | Q31: TAICHUNG | S31: KANWAY GLOBAL | T31: RIO GRANDE | U31: MERCOSUL SUAPE | V31: 88.104.328/0001-07 | X31: CALCADOS RAMARIM LTDA | Y31: MSL CORPORATE | Z31: OC 795127 | AA31: Collect | AB31: IM1471-25 | AE31: Pago | AF31: Recebido | AG31: Sem acerto com agente | AH31: Não aplicável | AJ31: 0.31 | AK31: 102 | AL31: 310 | AN31: LCL | AO31: 0 | AP31: 0 | AR31: 1 | AS31: 46037 | AT31: 46037 | AU31: =MONTH(AT31) -> 1 | AV31: OCEAN EXPRESS SERVICOS EM COMERCIO EXTERIOR LTDA | AY31: PF003961/25-01 | AZ31: CMAU7635610 | BA31: Bruna Kelsch | BD31: 77.91 | BE31: 341.14 | BF31: 337.08 | BG31: 337.08 | BH31: 414.99 | BI31: 414.99 | BK31: 46002.359 | BL31: 1941.6 | BM31: 1941.6 | BN31: 2282.74 | BO31: 2282.74 | BP31: 45996.167 | BQ31: 45996.264 | BR31: 0 | BT31: Divergência viagens | BU31: Falso | BW31: 0 | BX31: Ativo | BY31: Ativo
A32: 1 | B32: Marítimo importação | C32: Back to back | D32: IM1352-25 | E32: CALCADOS RAMARIM LTDA | F32: CALCADOS RAMARIM LTDA | G32: Jin Meng International Industry Co., Ltd. | H32: 45908 | I32: 45996.264 | J32: FOB | L32: 45874.35 | M32: 45874.35 | N32: Desembarcado | O32: MSL | P32: LXMRGD25082487RGD | Q32: XIAMEN | S32: TBA | T32: RIO GRANDE | U32: MERCOSUL SUAPE | V32: 88.104.328/0001-07 | X32: CALCADOS RAMARIM LTDA | Y32: MSL CORPORATE | Z32: PI NO.: 20250731001 | AA32: Collect | AB32: IM1352-25 | AE32: Pago | AF32: Recebido | AG32: Sem acerto com agente | AH32: Não aplicável | AJ32: 13.732 | AK32: 2221 | AL32: 13732 | AN32: LCL | AO32: 0 | AP32: 0 | AR32: 13.732 | AS32: 46037 | AT32: 46037 | AU32: =MONTH(AT32) -> 1 | AY32: PF003678/25-01 | AZ32: CMAU7635610 | BA32: Bruna Kelsch | BD32: 109.74 | BE32: 292.26 | BF32: 1200.88 | BG32: 1200.88 | BH32: 1310.62 | BI32: 1310.62 | BK32: 46002.361 | BL32: 6917.06 | BM32: 6917.06 | BN32: 7209.32 | BO32: 7209.32 | BP32: 45996.167 | BQ32: 45996.264 | BR32: 0 | BT32: Divergência viagens | BU32: Falso | BW32: 0 | BX32: Ativo | BY32: Ativo
A33: 1 | B33: Aéreo importação | C33: Back to back | D33: IA0653-25 | E33: PERBRAS EMPRESA BRASILEIRA DE PERFURACOES LTDA | F33: PERBRAS EMPRESA BRASILEIRA DE PERFURACOES LTDA | G33: Jiangsu Rushi Machinery Co., Ltd | H33: 45996 | I33: 45997 | J33: EXW | K33: 057-56004723 | L33: 45987.693 | M33: 45987.693 | N33: Desembarcado | O33: AIR FRANCE | P33: HYKC25110062 | Q33: PEQUIM (BEIJING) | T33: SALVADOR | V33: 15.126.451/0002-28 | X33: PERBRAS EMPRESA BRASILEIRA DE PERFURACOES LTDA | Y33: Shanghai Weiming Cargo Transportation co., Ltd. | AA33: Prepaid | AB33: IA0653-25 | AE33: Parcialmente pago | AF33: Recebido | AG33: Quitado | AH33: Desconsolidado | AJ33: 0.065 | AK33: 56 | AL33: 10.838 | AM33: 83 | AN33: Aéreo | AR33: 83 | AS33: 46031 | AT33: 46031 | AU33: =MONTH(AT33) -> 1 | AY33: PF006361/25-01 | BA33: Matheus Bourscheid | BB33: Mariana Reis | BD33: 43.57 | BE33: 544.36 | BF33: 1414.49 | BG33: 1404.96 | BH33: 1458.06 | BI33: 1458.06 | BK33: 46020.66 | BL33: 7760.97 | BM33: 7398.35 | BN33: 8305.33 | BO33: 8305.33 | BP33: 45997 | BQ33: 45997 | BT33: Tracking inativo | BU33: Falso | BW33: 0 | BX33: Ativo | BY33: Ativo
A34: 1 | B34: Aéreo importação | C34: Back to back | D34: IA0595-25 | E34: PERBRAS EMPRESA BRASILEIRA DE PERFURACOES LTDA | F34: PERBRAS EMPRESA BRASILEIRA DE PERFURACOES LTDA | G34: QINGDAO HONGNNENG POWER TECHNOLOGY | H34: 45996 | I34: 45997 | J34: EXW | K34: 057-56004723 | L34: 45966.372 | M34: 45966.372 | N34: Desembarcado | O34: AIR FRANCE | P34: HYKC25110056 | Q34: PEQUIM (BEIJING) | T34: SALVADOR | V34: 15.126.451/0002-28 | X34: PERBRAS EMPRESA BRASILEIRA DE PERFURACOES LTDA | Y34: Shanghai Weiming Cargo Transportation co., Ltd. | Z34: 22/10/2025 | AA34: Prepaid | AB34: IA0595-25 | AE34: Parcialmente pago | AF34: Recebido | AG34: Quitado | AH34: Desconsolidado | AJ34: 0.03 | AK34: 12 | AL34: 5.04 | AM34: 17 | AN34: Aéreo | AR34: 12 | AS34: 46031 | AT34: 46030 | AU34: =MONTH(AT34) -> 1 | AY34: PF005747/25-01 | BA34: Matheus Bourscheid | BB34: Mariana Reis | BD34: 48.14 | BE34: 349.27 | BF34: 385.94 | BG34: 383.63 | BH34: 434.1 | BI34: 434.08 | BK34: 46017.762 | BL34: 2123.43 | BM34: 2033.08 | BN34: 2472.7 | BO34: 2472.6 | BP34: 45997 | BQ34: 45997 | BS34: Back to back | BT34: Tracking inativo | BU34: Falso | BW34: 0 | BX34: Ativo | BY34: Ativo
A35: 1 | B35: Demurrage | C35: Back to back | D35: DEMU0003-26 | E35: MAVE COMERCIO DE ACESSORIOS LTDA | F35: MAVE COMERCIO DE ACESSORIOS LTDA | G35: VALENACERE S.A . | H35: 45933.668 | I35: 45998 | J35: FOB | K35: ONEYNB5BEEB36800 | L35: 46024.62 | M35: 46024.62 | N35: Desembarcado | O35: ONE | P35: KDSY25090134 | Q35: NINGBO | S35: ONE STRENGTH | T35: RIO GRANDE | U35: SEASPAN BELIEF | V35: 11.044.498/0001-00 | X35: WINNING TRADING S.A. (RO) | Y35: REACH LOGISTICS CO., LTD | Z35: ILOG: 3450/25 - P/I NO.:2025-VSB-004 - IM1777-25 | AA35: Collect | AB35: DEMU0003-26 | AE35: Sem pagamento | AF35: Sem recebimento | AG35: Sem acerto com agente | AH35: Não aplicável | AJ35: 24.49 | AK35: 25666.5 | AL35: 24490 | AN35: FCL | AO35: 0 | AP35: 1 | AQ35: 40 NOR | AR35: 25.666 | AT35: 46035 | AU35: =MONTH(AT35) -> 1 | AV35: LEADER LOGISTICS LTDA FILIAL ITJ | AY35: PF004809/25-01 | AZ35: ONEU9173765 | BA35: Matheus Bourscheid | BD35: 680 | BE35: 3862.8 | BF35: 380 | BG35: 380 | BH35: 1060 | BI35: 1060 | BK35: 46024.622 | BL35: 2188.8 | BM35: 2188.8 | BN35: 6051.6 | BO35: 6051.6 | BP35: 45998 | BR35: 2 | BT35: Tracking inativo | BU35: Falso | BW35: 0 | BX35: Ativo | BY35: Ativo
A36: 1 | B36: Demurrage | C36: Back to back | D36: DEMU0002-26 | E36: MAVE COMERCIO DE ACESSORIOS LTDA | F36: MAVE COMERCIO DE ACESSORIOS LTDA | G36: VALENACERE S.A . | H36: 45933 | I36: 45998 | J36: FOB | K36: ONEYNB5BEEB35700 | L36: 46024.611 | M36: 46024.611 | N36: Desembarcado | O36: ONE | P36: KDSY25090135 | Q36: NINGBO | S36: ONE STRENGTH | T36: RIO GRANDE | U36: SEASPAN BELIEF | V36: 11.044.498/0001-00 | X36: WINNING TRADING S.A. (RO) | Y36: REACH LOGISTICS CO., LTD | Z36: ILOG: 3449/25 - P/I NO.:2025-VSB-003 - IM1776-25 | AA36: Collect | AB36: DEMU0002-26 | AE36: Sem pagamento | AF36: Sem recebimento | AG36: Sem acerto com agente | AH36: Não aplicável | AJ36: 30.39 | AK36: 26321.4 | AL36: 30390 | AN36: FCL | AO36: 0 | AP36: 1 | AQ36: 40 NOR | AR36: 30.39 | AT36: 46035 | AU36: =MONTH(AT36) -> 1 | AV36: LEADER LOGISTICS LTDA FILIAL ITJ | AY36: PF004808/25-01 | AZ36: OTPU6308054 | BA36: Matheus Bourscheid | BD36: 680 | BE36: 3862.8 | BF36: 380 | BG36: 380 | BH36: 1060 | BI36: 1060 | BK36: 46024.615 | BL36: 2188.8 | BM36: 2188.8 | BN36: 6051.6 | BO36: 6051.6 | BP36: 45998 | BR36: 2 | BT36: Tracking inativo | BU36: Falso | BW36: 0 | BX36: Ativo | BY36: Ativo
A37: 1 | B37: Marítimo importação | C37: Back to back | D37: IM2071-25 | E37: VERALLIA BRASIL S.A. | F37: VERALLIA BRASIL S.A. | G37: CHINA BRIDGE HOLDINGS LIMITED | H37: 45964.853 | I37: 45998.686 | J37: FOB | K37: PSLSHASTS03667 | L37: 45951.45 | M37: 45951.45 | N37: Desembarcado | O37: KINGSHIP LINE LTDA | P37: SWS2510073 | Q37: SHANGHAI | S37: EVER FINE | T37: SANTOS | V37: 60.853.942/0007-30 | X37: VERALLIA BRASIL S.A. | Y37: (LCL) SHENZHEN SMOOTHWIN INTERNATIONAL | Z37: PO 5502161136 | AA37: Collect | AB37: IM2071-25 | AE37: Parcialmente pago | AF37: Em aberto | AG37: Quitado | AH37: Não aplicável | AJ37: 0.35 | AK37: 736 | AL37: 350 | AN37: LCL | AO37: 0 | AP37: 0 | AR37: 1 | AS37: 46029 | AT37: 46031 | AU37: =MONTH(AT37) -> 1 | AY37: PF005569/25-01 | AZ37: OTPU6160373 | BA37: Tiago Schneider | BB37: Mariana Reis | BD37: 136.42 | BE37: 816.27 | BF37: 500.16 | BG37: 498.24 | BH37: 636.58 | BI37: 0 | BK37: 46029.698 | BL37: 2809.79 | BM37: 2795.45 | BN37: 3626.06 | BO37: 0 | BR37: 0 | BT37: Divergência viagens | BU37: Falso | BW37: 0 | BX37: Ativo | BY37: Ativo
A38: 1 | B38: Marítimo importação | C38: Back to back | D38: IM2039-25 | E38: VERALLIA BRASIL S.A. | F38: VERALLIA BRASIL S.A. | G38: CHINA BRIDGE HOLDINGS LIMITED | H38: 45964.853 | I38: 45998.686 | J38: FOB | K38: PSLSHASTS03660 | L38: 45947.62 | M38: 45947.62 | N38: Desembarcado | O38: KINGSHIP LINE LTDA | P38: SWS2510065 | Q38: SHANGHAI | S38: EVER FINE | T38: SANTOS | V38: 60.853.942/0017-01 | X38: VERALLIA BRASIL S.A. | Y38: (LCL) SHENZHEN SMOOTHWIN INTERNATIONAL | Z38: PO 5502163794 +5502163792 | AA38: Collect | AB38: IM2039-25 | AE38: Parcialmente pago | AF38: Em aberto | AG38: Parcialmente quitado | AH38: Não aplicável | AJ38: 1.825 | AK38: 3010 | AL38: 1825 | AN38: LCL | AO38: 0 | AP38: 0 | AR38: 3.01 | AS38: 46031 | AT38: 46031 | AU38: =MONTH(AT38) -> 1 | AY38: PF005474/25-01 | AZ38: OTPU6160373 | BA38: Tiago Schneider | BB38: Mariana Reis | BD38: 157.52 | BE38: 962.64 | BF38: 1159.38 | BG38: 1094.46 | BH38: 1316.9 | BI38: 0 | BK38: 46028.647 | BL38: 6524.58 | BM38: 6151.39 | BN38: 7487.22 | BO38: 0 | BR38: 0 | BT38: Sincronizado | BU38: Falso | BW38: 0 | BX38: Ativo | BY38: Ativo
A39: 1 | B39: Marítimo importação | C39: Back to back | D39: IM1727-25 | E39: CALCADOS RAMARIM LTDA | F39: CALCADOS RAMARIM LTDA | G39: KEYI (FUJIAN) IMPORT AND EXPORT CO.,LTD. | H39: 45958.632 | I39: 45999.476 | J39: EXW | L39: 45912.682 | M39: 45912.682 | N39: Desembarcado | O39: ALLINK TRANSPORTES INTERNACIONAIS LTDA (ITAJAÍ) | P39: 16422080 | Q39: SHANGHAI | S39: HYUNDAI TOKYO | T39: RIO GRANDE | V39: 88.104.328/0001-07 | X39: CALCADOS RAMARIM LTDA | Y39: ALLINK TRANSPORTES INTERNACIONAIS LTDA (ITAJAÍ) | Z39: OC 799887 | AA39: Collect | AB39: IM1727-25 | AE39: Pago | AF39: Recebido | AG39: Sem acerto com agente | AH39: Não aplicável | AJ39: 0.174 | AK39: 91 | AL39: 174 | AN39: LCL | AO39: 0 | AP39: 0 | AR39: 1 | AS39: 46037 | AT39: 46037 | AU39: =MONTH(AT39) -> 1 | AV39: OCEAN EXPRESS SERVICOS EM COMERCIO EXTERIOR LTDA | AY39: PF004709/25-01 | AZ39: HMMU5493810 | BA39: Bruna Kelsch | BB39: Mariana Reis | BD39: 110.74 | BE39: 558.62 | BF39: 269.83 | BG39: 269.83 | BH39: 380.57 | BI39: 380.57 | BK39: 46002.369 | BL39: 1569.96 | BM39: 1569.96 | BN39: 2128.58 | BO39: 2128.58 | BP39: 45999.083 | BQ39: 45999.476 | BR39: 0 | BT39: Sincronizado | BU39: Falso | BW39: 0 | BX39: Ativo | BY39: Ativo
A40: 1 | B40: Marítimo importação | C40: Back to back | D40: IM1830-25 | E40: BRISA INDUSTRIA DE TECIDOS TECNOLOGICOS S.A | F40: BRISA INDUSTRIA DE TECIDOS TECNOLOGICOS S.A | G40: C.CENTAURUS TECHNOLOGY LTD | H40: 45945.833 | I40: 45999.858 | J40: FOB | K40: 259801566 | L40: 45924.435 | M40: 45924.435 | N40: Desembarcado | O40: MAERSK | P40: SZES25101014B | Q40: SHANGHAI | S40: AL NASRIYAH | T40: SALVADOR | U40: CMA CGM YUKON | V40: 02.036.823/0001-00 | X40: BRISA INDUSTRIA DE TECIDOS TECNOLOGICOS S.A | Y40: SHENZHEN EVERSEAS INTERNATIONAL LOGISTICS CO | Z40: CCTBS-0453 | AA40: Collect | AB40: IM1830-25 | AE40: Pago | AF40: Recebido | AG40: Quitado | AH40: Não aplicável | AL40: 0 | AN40: FCL | AO40: 1 | AP40: 0 | AQ40: 20 DRY BOX | AS40: 46006 | AT40: 46065 | AU40: =MONTH(AT40) -> 2 | AZ40: HASU1120310 | BA40: Enila Kawely | BD40: 262.34 | BE40: 1840.88 | BF40: 1085.93 | BG40: 1085.93 | BH40: 1348.27 | BI40: 1348.27 | BK40: 46014.452 | BL40: 5805.36 | BM40: 5890.2 | BN40: 7646.24 | BO40: 7646.24 | BP40: 45999.833 | BQ40: 45999.858 | BR40: 1 | BT40: Sincronizado | BU40: Falso | BX40: Ativo | BY40: Ativo
...

Sheet Resumo 2025
A3: Processos em andamento | B3: Data: 02/02/2026
A4: Analista | B4: Senioridade/cargo | C4: Ag booking | D4: Ag embarque | E4: Embarcado | F4: Ag faturamento | G4: Total | H4: Meta
A5: Matheus Bourscheid | B5: Junior | C5: 9 | D5: 28 | E5: 37 | F5: 10 | G5: =SUM(C5:F5) -> 84 | H5: 70- 80
A6: Tiago S | B6: Senior | C6: 13 | D6: 62 | E6: 68 | F6: 28 | G6: =SUM(C6:F6) -> 171 | H6: 110-140
A7: Enila Kawely | B7: Senior | C7: 13 | D7: 27 | E7: 43 | F7: 24 | G7: =SUM(C7:F7) -> 107 | H7: 110-140 | M7: 750 | N7: 100
A8: Bruna Kelsch | B8: Senior | C8: 14 | D8: 27 | E8: 73 | F8: 68 | G8: =SUM(C8:F8) -> 182 | H8: 110-140 | M8: 734 | N8: =M8*N7/M7 -> 97.866667
A9: Annie Audrien | B9: Senior | C9: 1 | D9: 0 | E9: 9 | F9: 9 | G9: =SUM(C9:F9) -> 19 | H9: 110-140 | I9: só Ropelato conduzindo
A10: Matheus R | B10: Supervisor | C10: 23 | D10: 40 | E10: 53 | F10: 11 | G10: =SUM(C10:F10) -> 127 | H10: 80-110
G11: =SUM(G5:G10) -> 690
H12: minimo | I12: MÁXIMO
H13: =70+(110*4)+80 -> 590 | I13: =80+(140*4)+110 -> 750
A14: Chegadas confirmadas por mês: | C14: 1 | D14: 2 | E14: 3 | F14: 4 | G14: 5 | H14: 6 | I14: 7 | J14: 8 | K14: 9 | L14: 10 | M14: 11 | N14: 12
A15: Analista | B15: Assistente | C15: Janeiro | D15: Fevereiro | E15: Março | F15: Abril | G15: Maio | H15: Junho | I15: Julho | J15: Agosto | K15: Setembro | L15: Outubro | M15: Novembro | N15: Dezembro | O15: Total
A16: Matheus Bourscheid | B16: Graziele Meytre | C16: =SUMIFS('Faturados 2025 HS'!$A:$A,'Faturados 2025 HS'!$BB:$BB,'Resumo 2025'!$A16,'Faturados 2025 HS'!$AU:$AU,'Resumo 2025'!C$14) -> 6 | D16: =SUMIFS('Faturados 2025 HS'!$A:$A,'Faturados 2025 HS'!$BB:$BB,'Resumo 2025'!$A16,'Faturados 2025 HS'!$AU:$AU,'Resumo 2025'!D$14) -> 6 | E16: =SUMIFS('Faturados 2025 HS'!$A:$A,'Faturados 2025 HS'!$BB:$BB,'Resumo 2025'!$A16,'Faturados 2025 HS'!$AU:$AU,'Resumo 2025'!E$14) -> 10 | F16: =SUMIFS('Faturados 2025 HS'!$A:$A,'Faturados 2025 HS'!$BB:$BB,'Resumo 2025'!$A16,'Faturados 2025 HS'!$AU:$AU,'Resumo 2025'!F$14) -> 13 | G16: =SUMIFS('Faturados 2025 HS'!$A:$A,'Faturados 2025 HS'!$BB:$BB,'Resumo 2025'!$A16,'Faturados 2025 HS'!$AU:$AU,'Resumo 2025'!G$14) -> 22 | H16: =SUMIFS('Faturados 2025 HS'!$A:$A,'Faturados 2025 HS'!$BB:$BB,'Resumo 2025'!$A16,'Faturados 2025 HS'!$AU:$AU,'Resumo 2025'!H$14) -> 19 | I16: =SUMIFS('Faturados 2025 HS'!$A:$A,'Faturados 2025 HS'!$BB:$BB,'Resumo 2025'!$A16,'Faturados 2025 HS'!$AU:$AU,'Resumo 2025'!I$14) -> 29 | J16: =SUMIFS('Faturados 2025 HS'!$A:$A,'Faturados 2025 HS'!$BB:$BB,'Resumo 2025'!$A16,'Faturados 2025 HS'!$AU:$AU,'Resumo 2025'!J$14) -> 37 | ... N16: =SUMIFS('Faturados 2025 HS'!$A:$A,'Faturados 2025 HS'!$BB:$BB,'Resumo 2025'!$A16,'Faturados 2025 HS'!$AU:$AU,'Resumo 2025'!N$14) -> 32 | O16: =SUM(C16:N16) -> 295
A17: Tiago Schneider | B17: Kailane Claudino | C17: =SUMIFS('Faturados 2025 HS'!$A:$A,'Faturados 2025 HS'!$BB:$BB,'Resumo 2025'!$A17,'Faturados 2025 HS'!$AU:$AU,'Resumo 2025'!C$14) -> 65 | D17: =SUMIFS('Faturados 2025 HS'!$A:$A,'Faturados 2025 HS'!$BB:$BB,'Resumo 2025'!$A17,'Faturados 2025 HS'!$AU:$AU,'Resumo 2025'!D$14) -> 33 | E17: =SUMIFS('Faturados 2025 HS'!$A:$A,'Faturados 2025 HS'!$BB:$BB,'Resumo 2025'!$A17,'Faturados 2025 HS'!$AU:$AU,'Resumo 2025'!E$14) -> 29 | F17: =SUMIFS('Faturados 2025 HS'!$A:$A,'Faturados 2025 HS'!$BB:$BB,'Resumo 2025'!$A17,'Faturados 2025 HS'!$AU:$AU,'Resumo 2025'!F$14) -> 27 | G17: =SUMIFS('Faturados 2025 HS'!$A:$A,'Faturados 2025 HS'!$BB:$BB,'Resumo 2025'!$A17,'Faturados 2025 HS'!$AU:$AU,'Resumo 2025'!G$14) -> 23 | H17: =SUMIFS('Faturados 2025 HS'!$A:$A,'Faturados 2025 HS'!$BB:$BB,'Resumo 2025'!$A17,'Faturados 2025 HS'!$AU:$AU,'Resumo 2025'!H$14) -> 41 | I17: =SUMIFS('Faturados 2025 HS'!$A:$A,'Faturados 2025 HS'!$BB:$BB,'Resumo 2025'!$A17,'Faturados 2025 HS'!$AU:$AU,'Resumo 2025'!I$14) -> 39 | J17: =SUMIFS('Faturados 2025 HS'!$A:$A,'Faturados 2025 HS'!$BB:$BB,'Resumo 2025'!$A17,'Faturados 2025 HS'!$AU:$AU,'Resumo 2025'!J$14) -> 49 | ... N17: =SUMIFS('Faturados 2025 HS'!$A:$A,'Faturados 2025 HS'!$BB:$BB,'Resumo 2025'!$A17,'Faturados 2025 HS'!$AU:$AU,'Resumo 2025'!N$14) -> 53 | O17: =SUM(C17:N17) -> 539
A18: Enila Kawely | B18: Manuela Gonçalves | C18: =SUMIFS('Faturados 2025 HS'!$A:$A,'Faturados 2025 HS'!$BB:$BB,'Resumo 2025'!$A18,'Faturados 2025 HS'!$AU:$AU,'Resumo 2025'!C$14) -> 19 | D18: =SUMIFS('Faturados 2025 HS'!$A:$A,'Faturados 2025 HS'!$BB:$BB,'Resumo 2025'!$A18,'Faturados 2025 HS'!$AU:$AU,'Resumo 2025'!D$14) -> 24 | E18: =SUMIFS('Faturados 2025 HS'!$A:$A,'Faturados 2025 HS'!$BB:$BB,'Resumo 2025'!$A18,'Faturados 2025 HS'!$AU:$AU,'Resumo 2025'!E$14) -> 27 | F18: =SUMIFS('Faturados 2025 HS'!$A:$A,'Faturados 2025 HS'!$BB:$BB,'Resumo 2025'!$A18,'Faturados 2025 HS'!$AU:$AU,'Resumo 2025'!F$14) -> 27 | G18: =SUMIFS('Faturados 2025 HS'!$A:$A,'Faturados 2025 HS'!$BB:$BB,'Resumo 2025'!$A18,'Faturados 2025 HS'!$AU:$AU,'Resumo 2025'!G$14) -> 32 | H18: =SUMIFS('Faturados 2025 HS'!$A:$A,'Faturados 2025 HS'!$BB:$BB,'Resumo 2025'!$A18,'Faturados 2025 HS'!$AU:$AU,'Resumo 2025'!H$14) -> 35 | I18: =SUMIFS('Faturados 2025 HS'!$A:$A,'Faturados 2025 HS'!$BB:$BB,'Resumo 2025'!$A18,'Faturados 2025 HS'!$AU:$AU,'Resumo 2025'!I$14) -> 40 | J18: =SUMIFS('Faturados 2025 HS'!$A:$A,'Faturados 2025 HS'!$BB:$BB,'Resumo 2025'!$A18,'Faturados 2025 HS'!$AU:$AU,'Resumo 2025'!J$14) -> 29 | ... N18: =SUMIFS('Faturados 2025 HS'!$A:$A,'Faturados 2025 HS'!$BB:$BB,'Resumo 2025'!$A18,'Faturados 2025 HS'!$AU:$AU,'Resumo 2025'!N$14) -> 39 | O18: =SUM(C18:N18) -> 390
A19: Gabriel Hilgert | B19: N/A | C19: =SUMIFS('Faturados 2025 HS'!$A:$A,'Faturados 2025 HS'!$BB:$BB,'Resumo 2025'!$A19,'Faturados 2025 HS'!$AU:$AU,'Resumo 2025'!C$14) -> 2 | D19: =SUMIFS('Faturados 2025 HS'!$A:$A,'Faturados 2025 HS'!$BB:$BB,'Resumo 2025'!$A19,'Faturados 2025 HS'!$AU:$AU,'Resumo 2025'!D$14) -> 16 | E19: =SUMIFS('Faturados 2025 HS'!$A:$A,'Faturados 2025 HS'!$BB:$BB,'Resumo 2025'!$A19,'Faturados 2025 HS'!$AU:$AU,'Resumo 2025'!E$14) -> 7 | F19: =SUMIFS('Faturados 2025 HS'!$A:$A,'Faturados 2025 HS'!$BB:$BB,'Resumo 2025'!$A19,'Faturados 2025 HS'!$AU:$AU,'Resumo 2025'!F$14) -> 2 | G19: =SUMIFS('Faturados 2025 HS'!$A:$A,'Faturados 2025 HS'!$BB:$BB,'Resumo 2025'!$A19,'Faturados 2025 HS'!$AU:$AU,'Resumo 2025'!G$14) -> 3 | H19: =SUMIFS('Faturados 2025 HS'!$A:$A,'Faturados 2025 HS'!$BB:$BB,'Resumo 2025'!$A19,'Faturados 2025 HS'!$AU:$AU,'Resumo 2025'!H$14) -> 4 | I19: =SUMIFS('Faturados 2025 HS'!$A:$A,'Faturados 2025 HS'!$BB:$BB,'Resumo 2025'!$A19,'Faturados 2025 HS'!$AU:$AU,'Resumo 2025'!I$14) -> 0 | J19: =SUMIFS('Faturados 2025 HS'!$A:$A,'Faturados 2025 HS'!$BB:$BB,'Resumo 2025'!$A19,'Faturados 2025 HS'!$AU:$AU,'Resumo 2025'!J$14) -> 3 | ... N19: =SUMIFS('Faturados 2025 HS'!$A:$A,'Faturados 2025 HS'!$BB:$BB,'Resumo 2025'!$A19,'Faturados 2025 HS'!$AU:$AU,'Resumo 2025'!N$14) -> 0 | O19: =SUM(C19:N19) -> 37 | P19: rebates | Q19: =O19 -> 37
